{
 "cells": [
  {
   "cell_type": "code",
   "execution_count": 6,
   "id": "5b9a3a28",
   "metadata": {},
   "outputs": [
    {
     "name": "stdout",
     "output_type": "stream",
     "text": [
      "Unexpected exception formatting exception. Falling back to standard exception\n"
     ]
    },
    {
     "name": "stderr",
     "output_type": "stream",
     "text": [
      "Traceback (most recent call last):\n",
      "  File \"C:\\Python311\\Lib\\site-packages\\IPython\\core\\interactiveshell.py\", line 3442, in run_code\n",
      "    exec(code_obj, self.user_global_ns, self.user_ns)\n",
      "  File \"C:\\Users\\HTCM\\AppData\\Local\\Temp\\ipykernel_8976\\328324305.py\", line 2, in <module>\n",
      "    import matplotlib.pyplot as plt\n",
      "ModuleNotFoundError: No module named 'matplotlib'\n",
      "\n",
      "During handling of the above exception, another exception occurred:\n",
      "\n",
      "Traceback (most recent call last):\n",
      "  File \"C:\\Python311\\Lib\\site-packages\\IPython\\core\\interactiveshell.py\", line 2057, in showtraceback\n",
      "    stb = self.InteractiveTB.structured_traceback(\n",
      "          ^^^^^^^^^^^^^^^^^^^^^^^^^^^^^^^^^^^^^^^^\n",
      "  File \"C:\\Python311\\Lib\\site-packages\\IPython\\core\\ultratb.py\", line 1118, in structured_traceback\n",
      "    return FormattedTB.structured_traceback(\n",
      "           ^^^^^^^^^^^^^^^^^^^^^^^^^^^^^^^^^\n",
      "  File \"C:\\Python311\\Lib\\site-packages\\IPython\\core\\ultratb.py\", line 1012, in structured_traceback\n",
      "    return VerboseTB.structured_traceback(\n",
      "           ^^^^^^^^^^^^^^^^^^^^^^^^^^^^^^^\n",
      "  File \"C:\\Python311\\Lib\\site-packages\\IPython\\core\\ultratb.py\", line 865, in structured_traceback\n",
      "    formatted_exception = self.format_exception_as_a_whole(etype, evalue, etb, number_of_lines_of_context,\n",
      "                          ^^^^^^^^^^^^^^^^^^^^^^^^^^^^^^^^^^^^^^^^^^^^^^^^^^^^^^^^^^^^^^^^^^^^^^^^^^^^^^^^\n",
      "  File \"C:\\Python311\\Lib\\site-packages\\IPython\\core\\ultratb.py\", line 818, in format_exception_as_a_whole\n",
      "    frames.append(self.format_record(r))\n",
      "                  ^^^^^^^^^^^^^^^^^^^^^\n",
      "  File \"C:\\Python311\\Lib\\site-packages\\IPython\\core\\ultratb.py\", line 736, in format_record\n",
      "    result += ''.join(_format_traceback_lines(frame_info.lines, Colors, self.has_colors, lvals))\n",
      "                                              ^^^^^^^^^^^^^^^^\n",
      "  File \"C:\\Python311\\Lib\\site-packages\\stack_data\\utils.py\", line 144, in cached_property_wrapper\n",
      "    value = obj.__dict__[self.func.__name__] = self.func(obj)\n",
      "                                               ^^^^^^^^^^^^^^\n",
      "  File \"C:\\Python311\\Lib\\site-packages\\stack_data\\core.py\", line 734, in lines\n",
      "    pieces = self.included_pieces\n",
      "             ^^^^^^^^^^^^^^^^^^^^\n",
      "  File \"C:\\Python311\\Lib\\site-packages\\stack_data\\utils.py\", line 144, in cached_property_wrapper\n",
      "    value = obj.__dict__[self.func.__name__] = self.func(obj)\n",
      "                                               ^^^^^^^^^^^^^^\n",
      "  File \"C:\\Python311\\Lib\\site-packages\\stack_data\\core.py\", line 677, in included_pieces\n",
      "    scope_pieces = self.scope_pieces\n",
      "                   ^^^^^^^^^^^^^^^^^\n",
      "  File \"C:\\Python311\\Lib\\site-packages\\stack_data\\utils.py\", line 144, in cached_property_wrapper\n",
      "    value = obj.__dict__[self.func.__name__] = self.func(obj)\n",
      "                                               ^^^^^^^^^^^^^^\n",
      "  File \"C:\\Python311\\Lib\\site-packages\\stack_data\\core.py\", line 614, in scope_pieces\n",
      "    scope_start, scope_end = self.source.line_range(self.scope)\n",
      "                             ^^^^^^^^^^^^^^^^^^^^^^^^^^^^^^^^^^\n",
      "  File \"C:\\Python311\\Lib\\site-packages\\stack_data\\core.py\", line 178, in line_range\n",
      "    return line_range(self.asttext(), node)\n",
      "                      ^^^^^^^^^^^^^^\n",
      "  File \"C:\\Python311\\Lib\\site-packages\\executing\\executing.py\", line 428, in asttext\n",
      "    self._asttext = ASTText(self.text, tree=self.tree, filename=self.filename)\n",
      "                    ^^^^^^^^^^^^^^^^^^^^^^^^^^^^^^^^^^^^^^^^^^^^^^^^^^^^^^^^^^\n",
      "  File \"C:\\Python311\\Lib\\site-packages\\asttokens\\asttokens.py\", line 307, in __init__\n",
      "    super(ASTText, self).__init__(source_text, filename)\n",
      "  File \"C:\\Python311\\Lib\\site-packages\\asttokens\\asttokens.py\", line 44, in __init__\n",
      "    source_text = six.ensure_text(source_text)\n",
      "                  ^^^^^^^^^^^^^^^\n",
      "AttributeError: module 'six' has no attribute 'ensure_text'\n"
     ]
    }
   ],
   "source": [
    "import numpy as np\n",
    "import matplotlib.pyplot as plt\n",
    "import pandas as pd"
   ]
  }
 ],
 "metadata": {
  "kernelspec": {
   "display_name": "Python 3 (ipykernel)",
   "language": "python",
   "name": "python3"
  },
  "language_info": {
   "codemirror_mode": {
    "name": "ipython",
    "version": 3
   },
   "file_extension": ".py",
   "mimetype": "text/x-python",
   "name": "python",
   "nbconvert_exporter": "python",
   "pygments_lexer": "ipython3",
   "version": "3.11.0"
  }
 },
 "nbformat": 4,
 "nbformat_minor": 5
}
